Workbook

Sheet Games
B1: Date | C1: Name | D1: Link | E1: Engine | F1: Type | G1: Visuals | H1: Status | I1: Main Tags | J1: Pat | K1: Mon | L1: Info
B2: 45136 | C2: Complex Society [v1.00.1b] [AbrokenA Productions] | D2: Here | E2: Ren'Py | F2: Sandbox | G2: Koikatsu | H2: Completed | I2: Harem, Big Tits, Male Protagonist, Milf, Incest | J2: 63 | K2: 326
B3: 45242 | C3: Waifu Slut School [v0.3.1] [mikiraus] | D3: Here | E3: Ren'Py | F3: Sandbox | G3: Koikatsu | H3: Active | I3: Animated, Male Protagonist, Vaginal Sex, Groping, Big Tits
B4: 44728 | C4: Alternative Universe [Demo] [EchoWix Games] | D4: Here | E4: Ren'Py | F4: Sandbox | G4: Koikatsu | H4: Abandoned | I4: Multiple Protagonist, Harem, Point & Click, Puzzle, POV | M4: x
B5: 44862 | C5: Greener Pastures [v0.13.5] [arcaos] | D5: Here | E5: Ren'Py | F5: Sandbox | G5: Koikatsu | H5: Completed | I5: Monster Girl, Pregnancy, Male Domination, Group Sex, Harem | J5: 98 | K5: 414
B6: 45215 | C6: Peerless Lust [v0.29 Public] [Darx24] | D6: Here | E6: Ren'Py | F6: Sandbox | G6: Koikatsu | H6: Active | I6: Harem, Animated, Group Sex, Lesbian, Milf | J6: 99 | K6: 462
B7: 44724 | C7: Harem Impact [v0.2] [RayAsher] | D7: Here | E7: Ren'Py | F7: Sandbox | G7: Koikatsu | H7: Active | I7: Animated, Male Protagonist, Romance, Adventure, Harem | J7: 4 | K7: 19
B8: 45150 | C8: Afterlife Harem [v0.3.9 Public] [Aph] | D8: Here | E8: Ren'Py | F8: Sandbox | G8: Koikatsu | H8: Active | I8: Dating Sim, Harem, RGP, Superpowers, Vaginal sex | J8: 195 | K8: 1273
A9: D | B9: 45203 | C9: My Hero Rising [v0.67] [Daraus] | D9: Here | E9: Ren'Py | F9: Sandbox | G9: Koikatsu | H9: Active | I9: Harem, Animated, Dating Sim, Parody, Corruption | J9: 225 | K9: 1090
B10: 45186 | C10: Love at First Tail [v0.4.3.1] [MrDracosaurus] | D10: Here | E10: Ren'Py | F10: Sandbox | G10: Koikatsu | H10: Active | I10: 3DCG, Romance, Furry, Monster Girl, Multiple endings | J10: 209 | K10: 689 | L10: Euros
B11: 45205 | C11: Falling Stars [v0.7.2.] [nyatd] | D11: Here | E11: Ren'Py | F11: Sandbox | G11: Koikatsu | H11: Active | I11: Humor, Harem, Romance, Group Sex, Male Protagonist | J11: 9 | K11: 51
B12: 44975 | C12: Black Rabbit Trainer [v0.4.0] [Jellyfluff Games] | D12: Here | E12: Ren'Py | F12: Sandbox | G12: Koikatsu | H12: Active
B13: 45243 | C13: Corrupted Kingdoms [v0.20.3] [ArcGames] | D13: Here | E13: Ren'Py | F13: Sandbox | G13: Koikatsu | H13: Active | I13: Harem, Corruption, Fantasy, Mind Control, Monster Girl | J13: 3840 | K13: 9057
B14: 45129 | C14: Reboot Love Part 2 [v2.6.7] [Reboot Love] | D14: Here | E14: Ren'Py | F14: Sandbox | G14: Koikatsu | H14: Active | I14: Pregnancy, Harem, Animated, Male protagonist, Superpowers | J14: 96 | K14: 618
B15: 45181 | C15: Adventurer Trainer [v0.1.7] [PastryIRL] | D15: Here | E15: Ren'Py | F15: Sandbox | G15: Koikatsu | H15: Active | I15: RPG, Fantasy, Humor, Harem, Parody | J15: 102
B16: 45112 | C16: Demons of the Hearth [v0.7.51] [Konvel] | D16: Here | E16: Ren'Py | F16: Sandbox | G16: Koikatsu | H16: Active | I16: Harem, Fantasy, Graphic Violence, Dating Sim, Superpowers
B17: 45193 | C17: Scarlet Law [v0.3.13] [JYP Games] | D17: Here | E17: Ren'Py | F17: Sandbox | G17: Koikatsu | H17: Active
B18: 45181 | C18: Fantasy Opposite [v0.4.1] [ThirtySevenGaming] | D18: Here | E18: Ren'Py | F18: Sandbox | G18: Koikatsu | H18: Active | I18: Furry, Shota, Milf, Futa/Trans, Incest | J18: 36 | K18: 171
B19: 45235 | C19: Lust Age [v0.17.0] [Keisi] | D19: Here | E19: Ren'Py | F19: Sandbox | G19: Koikatsu | H19: Active | I19: Harem, Male Protagonist, Teasing, RPG, Humor | J19: 39 | K19: 1109 | L19: Euros
B20: 44813 | C20: I'm a Pimp in Another World [v0.3] [Arinasa] | D20: Here | E20: Ren'Py | F20: Sandbox | G20: Koikatsu | H20: Active
B21: 45170 | C21: Harem Residence [v0.111] [Vendena] | D21: Here | E21: Ren'Py | F21: Sandbox | G21: Koikatsu | H21: Active
B22: 45092 | C22: Genex Love [v0.3.5b] [Reboot Love] | D22: Here | E22: Ren'Py | F22: Visual Novel | G22: Koikatsu | H22: Active | I22: Harem, Animated, Male protagonist, Superpowers, Romance | J22: 96 | K22: 618
B23: 45246 | C23: Konoha Training [Ch.2 v0.7] [KonohaTraining] | D23: Here | E23: Ren'Py | F23: Sandbox | G23: Koikatsu | H23: Active | I23: Pregnancy, Harem, Corruption, Mind control, Male protagonist
A24: D | B24: 44923 | C24: Champion of Realms [v0.74 Public] [Zimon] | D24: Here | E24: Ren'Py | F24: Sandbox | G24: Koikatsu | H24: Active | I24: Monster Girl, Harem, Romance, Animated, Adventure | L24: Drama
B25: 45106 | C25: Melatonin Magiks [Ch.3 v3.0 Public] [LaCokaGaming] | D25: Here | E25: Ren'Py | F25: Sandbox | G25: Koikatsu | H25: Active | I25: Harem, Fantasy, Sci-fi, Group sex, Monster girl | J25: 42 | K25: 198
B26: 45202 | C26: Wolf Complex [v0.9.1] [RecentlyLuckyMan] | D26: Here | E26: Ren'Py | F26: Sandbox | G26: Koikatsu | H26: Active | I26: Incest, Simulator, Male Protagonist, 3DCG, Animated
B27: 44966 | C27: Last Wish [v0.3] [Avian] | D27: Here | E27: Ren'Py | F27: Sandbox | G27: Koikatsu | H27: Active | I27: Harem, Fantasy, Romance, Humor, Creampie | J27: 7 | K27: 37
B28: 45160 | C28: School of Love: Clubs! [v0.1.8.5] [NijuKozo] | D28: Here | E28: Ren'Py | F28: Sandbox | G28: Koikatsu | H28: Active
B29: 45157 | C29: Lewd Town Adventures [v0.14.3] [Jamleng Games] | D29: Here | E29: Ren'Py | F29: Sandbox | G29: Koikatsu | H29: Active | I29: Humor, Corruption, Drugs, Pregnancy, Incest | L29: +1Kp Sub
B30: 44931 | C30: Lessons in Love [v0.28.0] [Selebus] | D30: Here | E30: Ren'Py | F30: Sandbox | G30: Koikatsu | H30: Active
B31: 44964 | C31: Vixens Tail: Duskvale [v1.0] [Fluxcarnal] | D31: Here | E31: Ren'Py | F31: Sandbox | G31: Koikatsu | H31: Completed | I31: Futa/trans, Futa/trans Protagonist, Adventure, Monster Girl, Fantasy | J31: 0 | K31: 0 | L31: No $
B32: 44637 | C32: Alter Love [v0.0.1] [ChicoNet] | D32: Here | E32: Ren'Py | F32: Sandbox | G32: Koikatsu | H32: Abandoned | I32: Corruption, Harem, Incest, Teasing, Voyeurism | J32: Temi
B33: 44636 | C33: Changing Life [v0.4.1] [WombatGames] | D33: Here | E33: Ren'Py | F33: Sandbox | G33: Koikatsu | H33: Abandoned
B34: 45199 | C34: HS Tutor [v0.15.0] [TK8000] | D34: Here | E34: Ren'Py | F34: Sandbox | G34: Koikatsu | H34: Active
B35: 44959 | C35: Depraved Town: Remake [v0.3.0] [JustAnotherDegenerate] | D35: Here | E35: Ren'Py | F35: Sandbox | G35: Koikatsu | H35: Active | I35: 3DCG, Incest, Corruption, Harem, Milf | J35: 45
B36: 44617 | C36: Symphonic Love [v0.5] [IndieGO Studios] | D36: Here | E36: Ren'Py | F36: Sandbox | G36: Koikatsu | H36: Abandoned | I36: Dating Sim, Vaginal, Creampie, Gay, Male Protagonist
B37: 44776 | C37: ISOR [v0.7 Bugfix] [Mystic CRO] | D37: Here | E37: Ren'Py | F37: Sandbox | G37: Koikatsu | H37: Active | I37: Harem, Romance, Fantasy, Animated, Loli | J37: 22
B38: 44928 | C38: Hom Factory: My Monster Girl Tower [v3.0.1] [Hom Factory Devs] | D38: Here | E38: Ren'Py | F38: Sandbox | G38: Koikatsu | H38: Abandoned | I38: Harem, Adventure, Fantasy, Group Sex, Monster Girl | J38: 21 | K38: 122
B39: 44597 | C39: Morgan and Pestle [v0.1] [cyborgturtle] | D39: Here | E39: Ren'Py | F39: Sandbox | G39: Koikatsu | H39: Active | I39: Futa/trans, Transformation, Big Tits, Big Ass, Monster Girl
B40: 44927 | C40: Twisted World [v0.7.2] [SnatsGames] | D40: Here | E40: Ren'Py | F40: Sandbox | G40: Koikatsu | H40: Active
...

Sheet Information
B2: Date | C2: Green color: It means that it's the game's release and still has no updates at the moment of updating the doc.
C3: Grey/No color: The last time the game was updated at the momento of updating the doc, The date will be changed only once per month.
C4: Note: Some games were released as Complete games. Those games's date aren't in green color.
B6: Name | C6: The name is a copy-paste of however the game was titled at the moment. The version number might be outdated but the Date should be always the right one.
B8: Type | C8: Visual Novel: Game with VN format. It can be kinetic or not, it can be more or less linear, it can have minigames or not, but it doesn't use the classic "Sandbox" map.
C9: Sandbox: Game which features a map where the player can go to different places and interact with different things.
C10: RPG: Game with a RPG style but without TBC as one of its gameplay mechanics.
C11: TBC: Games with a Turn Based Combat system as one of its gameple mechanics.
C12: Management: Game which focuses on the management of resources in order to progress the game.
C13: Simulator: Games designed to closely simulate real world activities. It can be used for fantasy activities as well as long as it tries to present a "realistic look" of said activity.
C14: Collection: A collection of games in one thread which may or may not fit into various of the already mentioned categories.
C15: ----: Games who's type couldn't be defined.
C16: Note: Game's type are associated, but not limited, to engines. It's normal to find a Ren'Py VN and RPGM TBC, but it's also possible to find Ren'Py TBC and RPGM VN.
B18: Visuals | C18: Koikatsu: Games done using the Koikatsu, as simple as that.
C19: COM3D2: Games done with Custom Order Maid 3D2.
C20: Others: Games done with other games/softwares but still too irrelevant to have its own tag. Some examples right now are VROID, HM, 3DCG.
C21: Undefined: Games done with an unidentified game/software or original software.
C22: Traced: Games dones with any of the already mentioned categories but the developers draws or "traces" on the CGs to imprint a more 2D/original style on the final product.
C23: AI: Games done with AI but the developer uses Koikatu/COM32D CGs to feed the AI
B25: Status | C25: The status it's the same of F95's thread at the moment of the last time I updated the game in the list, unless I have the word of the dev stating something different.
B27: Main Tags | C27: I asked almost all devs on the list to describe their games using only 5 tags, not all of them replied. Other games are tagged thanks to "hardcore fans" in each game's thread who replied my question. Other games are tagged by me after playing them.
B30: Filters | C30: For a simple A-Z or Z-A order you can use the box next to the column's letter. If you want to filter things by categories, click the Filter icon next to the Printer in the up_left corner and check/uncheck the categories. If you want to undo any filters/order, click on the X in the up_right corner.
B33: General Note | C33: The unfiltered order is the one in the main F95 thread at the moment of making this Google Sheet. Games released after that will go to the botton of the list.
B35: Submit your tags | C35: If you are a developer and I haven't contacted you yet, please DM Adabelitoo in F95zone | I35: Last Date and Status check: 2023-01-10
I36: Last Total Status check: 2023-05-04

Sheet Private
A2: =AVERAGE(Games!J:J) -> 138.59091 | B2: Promedio patreons ciego | D2: =AVERAGE(Games!K:K) -> 556.74074 | E2: Promedio dinero ciego
A3: =MAX(Games!J:J) -> 3840 | B3: Max patreons | D3: =MAX(Games!K:K) -> 9057 | E3: Max dinero
A5: =COUNTIFS(Games!J:J,">=1",Games!J:J,"<=50") -> 28 | B5: Cant patreon entre 1-50 | D5: =COUNTIFS(Games!K:K,">=1",Games!K:K,"<=50") -> 9 | E5: Cant dinero entre 1-50
A6: =COUNTIFS(Games!J:J,">=51",Games!J:J,"<=100") -> 11 | B6: Cant patreon entre 51-100 | D6: =COUNTIFS(Games!K:K,">=51",Games!K:K,"<=100") -> 4 | E6: Cant dinero entre 50-100
A7: =COUNTIFS(Games!J:J,">=101",Games!J:J,"<=150") -> 7 | B7: Cant patreon entre 101-150 | D7: =COUNTIFS(Games!K:K,">=1001",Games!K:K,"<=2000") -> 4 | E7: Cant dinero entre 101-200
A8: =COUNTIFS(Games!J:J,">=151",Games!J:J,"<=200") -> 5 | B8: Cant patreon entre 151-200 | D8: =COUNTIFS(Games!K:K,">=201",Games!K:K,"<=300") -> 2 | E8: Cant dinero entre 201-300
A9: =COUNTIFS(Games!J:J,">=201",Games!J:J,"<=250") -> 6 | B9: Cant patreon entre 201-250 | D9: =COUNTIFS(Games!K:K,">=301",Games!K:K,"<=400") -> 1 | E9: Cant dinero entre 301-400
A10: =COUNTIFS(Games!J:J,">=251",Games!J:J,"<=300") -> 1 | B10: Cant patreon entre 251-300 | D10: =COUNTIFS(Games!K:K,">=401",Games!K:K,"<=500") -> 2 | E10: Cant dinero entre 401-500
A11: =COUNTIFS(Games!J:J,">=301",Games!J:J,"<=400") -> 0 | B11: Cant patreon entre 301-400 | D11: =COUNTIFS(Games!K:K,">=501",Games!K:K,"<=750") -> 16 | E11: Cant dinero entre 501-750
A12: =COUNTIFS(Games!J:J,">=401",Games!J:J,"<=500") -> 1 | B12: Cant patreon entre 401-500 | D12: =COUNTIFS(Games!K:K,">=751",Games!K:K,"<=1000") -> 1 | E12: Cant dinero entre 751-1000
A13: =COUNTIFS(Games!J:J,">=501",Games!J:J,"<=750") -> 0 | B13: Cant patreon entre 501-750 | D13: =COUNTIFS(Games!K:K,">=1001",Games!K:K,"<=2000") -> 4 | E13: Cant dinero entre 1001-2000
A14: =COUNTIFS(Games!J:J,">=751",Games!J:J,"<=1000") -> 0 | B14: Cant patreon entre 751-1000 | D14: =COUNTIFS(Games!K:K,">=2001",Games!K:K,"<=3000") -> 1 | E14: Cant dinero entre 2001-3000
A15: =COUNTIFS(Games!J:J,">=1001",Games!J:J,"<=1500") -> 0 | B15: Cant patreon entre 1001-1500 | D15: =COUNTIFS(Games!K:K,">=3001",Games!K:K,"<=5000") -> 0 | E15: Cant dinero entre 3001-5000
A16: =COUNTIFS(Games!J:J,">=1501",Games!J:J,"<=2000") -> 0 | B16: Cant patreon entre 1501-2000 | D16: =COUNTIFS(Games!K:K,">=5001",Games!K:K,"<=7000") -> 0 | E16: Cant dinero entre 5001-7000
A17: =COUNTIF(Games!J:J,">=2001") -> 1 | B17: Cant patreon 2001 o mas | D17: =COUNTIF(Games!K:K,">=7001") -> 1 | E17: Cant dinero 7001 o mas
